<sdf version="1.6">
	<model name="msj_platform">
		<link name="base">
			<self_collide>false</self_collide>
			<kinematic>true</kinematic>
			<pose frame="">0.0 0.0 0.0 0.0 -0.0 0.0</pose>
			<inertial>
				<pose frame="">0.0 0.0 0.0 0 0 0</pose>
				<mass>4.7878299078281294</mass>
				<inertia>
					<ixx>0.05972535129798961</ixx>
					<ixy>-0.00012363610327145556</ixy>
					<ixz>0.00036205602174036784</ixz>
					<iyy>0.0597092739824584</iyy>
					<iyz>0.00013650635541912796</iyz>
					<izz>0.06052438458508023</izz>
				</inertia>
			</inertial>
			<collision name="base_collision">
				<geometry>
					<mesh>
						<uri>model://msj_platform/meshes/collisions/base.dae</uri>
						<scale>0.001 0.001 0.001</scale>
					</mesh>
				</geometry>
			</collision>
			<visual name="base_visual">
				<geometry>
					<mesh>
						<uri>model://msj_platform/meshes/visuals/base.dae</uri>
						<scale>0.001 0.001 0.001</scale>
					</mesh>
				</geometry>
			</visual>
		</link>
		<link name="top">
			<self_collide>false</self_collide>
			<pose frame="">0.007571428571428571 -0.006 0.1615714285714286 0.0 -0.0 0.0</pose>
			<inertial>
				<pose frame="">0.0 0.0 0.0 0 0 0</pose>
				<mass>0.23742047095738525</mass>
				<inertia>
					<ixx>0.005494864784193527</ixx>
					<ixy>1.0785733720890608e-05</ixy>
					<ixz>0.00021464915445619628</ixz>
					<iyy>0.005499927976165427</iyy>
					<iyz>-0.00027086653561933006</iyz>
					<izz>0.00012507297242491172</izz>
				</inertia>
			</inertial>
			<collision name="top_collision">
				<geometry>
					<mesh>
						<uri>model://msj_platform/meshes/collisions/top.dae</uri>
						<scale>0.001 0.001 0.001</scale>
					</mesh>
				</geometry>
			</collision>
			<visual name="top_visual">
				<geometry>
					<mesh>
						<uri>model://msj_platform/meshes/visuals/top.dae</uri>
						<scale>0.001 0.001 0.001</scale>
					</mesh>
				</geometry>
			</visual>
		</link>
		<link name="sphere_link1">
			<self_collide>false</self_collide>
			<pose frame="">0.007571428571428578 -0.0059999999999999975 0.10800000000000003 0.0 -0.0 0.0</pose>
			<inertial>
				<pose frame="">0.0 0.0 0.0 0 0 0</pose>
				<mass>0.06979038134801685</mass>
				<inertia>
					<ixx>0.000828194739444481</ixx>
					<ixy>3.1704773240956278e-06</ixy>
					<ixz>4.52241671135149e-05</ixz>
					<iyy>0.0008296831261487397</iyy>
					<iyz>-5.706859183372124e-05</iyz>
					<izz>1.81605718339997e-05</izz>
				</inertia>
			</inertial>
			<collision name="sphere_link1_collision">
				<geometry>
					<mesh>
						<uri>model://msj_platform/meshes/collisions/sphere_link1.dae</uri>
						<scale>0.001 0.001 0.001</scale>
					</mesh>
				</geometry>
			</collision>
			<visual name="sphere_link1_visual">
				<geometry>
					<mesh>
						<uri>model://msj_platform/meshes/visuals/sphere_link1.dae</uri>
						<scale>0.001 0.001 0.001</scale>
					</mesh>
				</geometry>
			</visual>
		</link>
		<link name="sphere_link2">
			<self_collide>false</self_collide>
			<pose frame="">0.007571428571428586 -0.006000000062483437 0.10799999990919075 0.0 -0.0 0.0</pose>
			<inertial>
				<pose frame="">0.0 0.0 0.0 0 0 0</pose>
				<mass>0.04678255760927329</mass>
				<inertia>
					<ixx>0.0005526173565767919</ixx>
					<ixy>2.1252647820964382e-06</ixy>
					<ixz>3.03150976586011e-05</ixz>
					<iyy>0.0005536150662576664</iyy>
					<iyz>-3.825476564718879e-05</iyz>
					<izz>9.627487289655988e-06</izz>
				</inertia>
			</inertial>
			<collision name="sphere_link2_collision">
				<geometry>
					<mesh>
						<uri>model://msj_platform/meshes/collisions/sphere_link2.dae</uri>
						<scale>0.001 0.001 0.001</scale>
					</mesh>
				</geometry>
			</collision>
			<visual name="sphere_link2_visual">
				<geometry>
					<mesh>
						<uri>model://msj_platform/meshes/visuals/sphere_link2.dae</uri>
						<scale>0.001 0.001 0.001</scale>
					</mesh>
				</geometry>
			</visual>
		</link>
		<joint name="sphere_axis0" type="revolute">
			<parent>base</parent>
			<child>sphere_link1</child>
			<pose frame="">-5.551115123125783e-18 -3.3306690738754695e-18 -1.7763568394002505e-17 0 0 0</pose>
			<axis>
				<xyz>1 0 0</xyz>
				<limit>
					<lower>-3.141592653589793</lower>
					<upper>3.141592653589793</upper>
				</limit>
				<use_parent_model_frame>0</use_parent_model_frame>
			</axis>
		</joint>
		<joint name="sphere_axis1" type="revolute">
			<parent>sphere_link1</parent>
			<child>sphere_link2</child>
			<pose frame="">-1.3322676295501878e-17 6.248343620285368e-11 9.080926233195896e-11 0 0 0</pose>
			<axis>
				<xyz>0 1 0</xyz>
				<limit>
					<lower>-3.141592653589793</lower>
					<upper>3.141592653589793</upper>
				</limit>
				<use_parent_model_frame>0</use_parent_model_frame>
			</axis>
		</joint>
		<joint name="sphere_axis2" type="revolute">
			<parent>sphere_link2</parent>
			<child>top</child>
			<pose frame="">8.881784197001253e-18 -1.1102230246251566e-18 -0.053571428571428575 0 0 0</pose>
			<axis>
				<xyz>0 0 1</xyz>
				<limit>
					<lower>-3.141592653589793</lower>
					<upper>3.141592653589793</upper>
				</limit>
				<use_parent_model_frame>0</use_parent_model_frame>
			</axis>
		</joint>

		<plugin filename="libcardsflow_gazebo_plugin.so" name="cardsflow_gazebo_plugin">
			
				
					
				
				
					
				
			
			
				
					
				
				
					
				
			
			
				
					
				
				
					
				
			
			
				
					
				
				
					
				
			
			
				
					
				
				
					
				
			
			
				
					
				
				
					
				
			
			
				
					
				
				
					
				
			
			
				
					
				
				
					
				
			
		</plugin>
	</model>
</sdf>